Workbook

Sheet Terrorism Template
A1: Address Details | K1: Commerical Property | M1: Business Interruption | O1: Loss of Rent
A2: Country | B2: Address Line 1 | C2: Address Line 2 | D2: Town/City | E2: State/Province (US/AUS/Canada only) | F2: County (all other territories) | G2: Post/Zip Code | H2: Latitude | I2: Longitude | J2: Building Use | K2: Property Declared Value | L2: Content Damage Sum Insured | M2: Actual Loss Sustained Sum Insured | N2: ICOW Sum Insured | O2: Loss of Rent Sum Insured | P2: Alternative Accommodation Sum Insured

Sheet Floating Values
A1: Commercial Property | B1: Business Interruption | D1: Loss of Rent
A2: Content Damage Sum Insured | B2: Actual Loss Sustained Sum Insured | C2: ICOW Sum Insured | D2: Loss of Rent Sum Insured | E2: Alternative Accommodation Sum Insured

Sheet First Loss Limit
A1: First Loss Limit

Sheet Validation
A1: Address Details | K1: Commerical Property
A2: Country | B2: Address Line 1 | C2: Address Line 2 | D2: Town/City | E2: State/Province (US/AUS/Canada only) | F2: County (all other territories) | G2: Post/Zip Code | H2: Latitude | I2: Longitude | J2: Building Use | K2: Property Declared Value | L2: Content Damage Sum Insured | M2: Contents Type | N2: Actual Loss Sustained Sum Insured | O2: Rent Payable | P2: ICOW Sum Insured | Q2: AICOW Sum Insured | R2: Type | S2: Loss of Rent Sum Insured | T2: Alternative Accommodation Sum Insured
A3: =COUNTIF(Tables!$A$3:$A$167,'Terrorism Template'!A3) -> 0 | E3: =COUNTIF(Tables!$C$3:$E$59,'Terrorism Template'!A3) -> 0
A4: =COUNTIF(Tables!$A$3:$A$167,'Terrorism Template'!A4) -> 0 | E4: =COUNTIF(Tables!$C$3:$E$59,'Terrorism Template'!A4) -> 0
A5: =COUNTIF(Tables!$A$3:$A$167,'Terrorism Template'!A5) -> 0 | E5: =COUNTIF(Tables!$C$3:$E$59,'Terrorism Template'!A5) -> 0
A6: =COUNTIF(Tables!$A$3:$A$167,'Terrorism Template'!A6) -> 0 | E6: =COUNTIF(Tables!$C$3:$E$59,'Terrorism Template'!A6) -> 0
A7: =COUNTIF(Tables!$A$3:$A$167,'Terrorism Template'!A7) -> 0 | E7: =COUNTIF(Tables!$C$3:$E$59,'Terrorism Template'!A7) -> 0
A8: =COUNTIF(Tables!$A$3:$A$167,'Terrorism Template'!A8) -> 0 | E8: =COUNTIF(Tables!$C$3:$E$59,'Terrorism Template'!A8) -> 0
A9: =COUNTIF(Tables!$A$3:$A$167,'Terrorism Template'!A9) -> 0 | E9: =COUNTIF(Tables!$C$3:$E$59,'Terrorism Template'!A9) -> 0
A10: =COUNTIF(Tables!$A$3:$A$167,'Terrorism Template'!A10) -> 0 | E10: =COUNTIF(Tables!$C$3:$E$59,'Terrorism Template'!A10) -> 0
A11: =COUNTIF(Tables!$A$3:$A$167,'Terrorism Template'!A11) -> 0 | E11: =COUNTIF(Tables!$C$3:$E$59,'Terrorism Template'!A11) -> 0
A12: =COUNTIF(Tables!$A$3:$A$167,'Terrorism Template'!A12) -> 0 | E12: =COUNTIF(Tables!$C$3:$E$59,'Terrorism Template'!A12) -> 0
A13: =COUNTIF(Tables!$A$3:$A$167,'Terrorism Template'!A13) -> 0 | E13: =COUNTIF(Tables!$C$3:$E$59,'Terrorism Template'!A13) -> 0
A14: =COUNTIF(Tables!$A$3:$A$167,'Terrorism Template'!A14) -> 0 | E14: =COUNTIF(Tables!$C$3:$E$59,'Terrorism Template'!A14) -> 0
... A1022: =COUNTIF(Tables!$A$3:$A$167,'Terrorism Template'!A1022) -> 0 | E1022: =COUNTIF(Tables!$C$3:$E$59,'Terrorism Template'!A1022) -> 0

Sheet Tables
A2: Country | C2: US | D2: Australia | E2: Canada | H2: Building Use | J2: Contents Type
A3: Albania | C3: Alaska | D3: Australian Capital Territory | E3: Alberta | H3: Agriculture - Excluding Greenhouses | J3: Fixed
A4: Algeria | C4: Alabama | D4: Northern Territory | E4: British Columbia | H4: Appartment/ Flats/ Residential | J4: Floating
A5: Andorra | C5: Arkansas | D5: New South Wales | E5: Manitoba | H5: Bakery - Deep fat frying
A6: Anguilla | C6: American Samoa | D6: Queensland | E6: New Brunswick | H6: Bakery - No frying
A7: Antigua | C7: Arizona | D7: South Australia | E7: Newfoundland | H7: Bank
A8: Argentina | C8: California | D8: Tasmania | E8: Nova Scotia | H8: Bottling/Canning
A9: Armenia | C9: Colorado | D9: Victoria | E9: Northwest Territories | H9: Bowling Alley
A10: Aruba | C10: Connecticut | D10: Western Australia | E10: Nunavut | H10: Brewery/Microbrewery
A11: Australia | C11: District of Columbia | E11: Ontario | H11: Broadcasting/News studio/Recording studio
A12: Austria | C12: Delaware | E12: Prince Edward Island | H12: Condo Owners/Condo Associations (Excluding third party tenancies)
A13: Azerbaijan | C13: Florida | E13: Quebec | H13: Condo Owners/Condo Associations (Including third party tenancies)
A14: Bahamas | C14: Georgia | E14: Saskatchewan | H14: Church
A15: Bahrain | C15: Guam | E15: Yukon | H15: Cinema
A16: Bangladesh | C16: Hawaii | H16: Convenience store
A17: Barbados | C17: Iowa | H17: Crematorium
A18: Belgium | C18: Idaho | H18: Data centre
A19: Bermuda | C19: Illinois | H19: Distillery
A20: Bolivia | C20: Indiana | H20: Doctors/Dentist/Medical Clinic
A21: Brazil | C21: Kansas | H21: Dry Cleaner
A22: British Virgin Islands | C22: Kentucky | H22: Golf club and/or country club
A23: Bulgaria | C23: Louisiana | H23: Gym
A24: Burundi | C24: Massachusetts | H24: Hopsital
A25: Cambodia | C25: Maryland | H25: Hotel - with Restaurant
A26: Cameroon | C26: Maine | H26: Hotel - without Restaurant
A27: Canada | C27: Marshall Islands | H27: Jewellers
... A59: Greece | C59: Wyoming | H59: Mills - Grain
A60: Grenada | H60: Mills - Sugar
A61: Guam | H61: Museum/Art Gallery/Exhibition Centre
A62: Guatemala | H62: Office
A63: Guernsey | H63: Pharmacy
A64: Guinea | H64: Printing/Publishing
A65: Guyana | H65: R&D
A66: Honduras | H66: R&D - Own R&D inc cold storage
A67: Honduras | H67: R&D - Own R&D NO cold storage
A68: Hong Kong | H68: R&D - services inc cold storage
A69: Hungary | H69: R&D - services NO cold storage
A70: Iceland | H70: Restaurant - Deep Fat Frying
A71: India | H71: Restaurant - No Frying
... A99: Mali | H99: Woodworking - No heat
...
